[2021-11-11 13:01:22,899] {taskinstance.py:1035} INFO - Dependencies all met for <TaskInstance: dag-2.model_D manual__2021-11-11T13:01:19.250340+00:00 [queued]>
[2021-11-11 13:01:22,919] {taskinstance.py:1035} INFO - Dependencies all met for <TaskInstance: dag-2.model_D manual__2021-11-11T13:01:19.250340+00:00 [queued]>
[2021-11-11 13:01:22,921] {taskinstance.py:1241} INFO - 
--------------------------------------------------------------------------------
[2021-11-11 13:01:22,923] {taskinstance.py:1242} INFO - Starting attempt 1 of 1
[2021-11-11 13:01:22,924] {taskinstance.py:1243} INFO - 
--------------------------------------------------------------------------------
[2021-11-11 13:01:22,955] {taskinstance.py:1262} INFO - Executing <Task(BranchPythonOperator): model_D> on 2021-11-11 13:01:19.250340+00:00
[2021-11-11 13:01:22,964] {standard_task_runner.py:52} INFO - Started process 4201 to run task
[2021-11-11 13:01:22,984] {standard_task_runner.py:76} INFO - Running: ['***', 'tasks', 'run', 'dag-2', 'model_D', 'manual__2021-11-11T13:01:19.250340+00:00', '--job-id', '18', '--raw', '--subdir', 'DAGS_FOLDER/DAG-2.py', '--cfg-path', '/tmp/tmpsxj2_p0t', '--error-file', '/tmp/tmptynzhsup']
[2021-11-11 13:01:22,991] {standard_task_runner.py:77} INFO - Job 18: Subtask model_D
[2021-11-11 13:01:23,074] {logging_mixin.py:109} INFO - Running <TaskInstance: dag-2.model_D manual__2021-11-11T13:01:19.250340+00:00 [running]> on host 150ca14c9dd9
[2021-11-11 13:01:23,135] {taskinstance.py:1429} INFO - Exporting the following env vars:
AIRFLOW_CTX_DAG_OWNER=***
AIRFLOW_CTX_DAG_ID=dag-2
AIRFLOW_CTX_TASK_ID=model_D
AIRFLOW_CTX_EXECUTION_DATE=2021-11-11T13:01:19.250340+00:00
AIRFLOW_CTX_DAG_RUN_ID=manual__2021-11-11T13:01:19.250340+00:00
[2021-11-11 13:01:23,139] {taskinstance.py:1703} ERROR - Task failed with exception
Traceback (most recent call last):
  File "/home/airflow/.local/lib/python3.7/site-packages/airflow/models/taskinstance.py", line 1332, in _run_raw_task
    self._execute_task_with_callbacks(context)
  File "/home/airflow/.local/lib/python3.7/site-packages/airflow/models/taskinstance.py", line 1458, in _execute_task_with_callbacks
    result = self._execute_task(context, self.task)
  File "/home/airflow/.local/lib/python3.7/site-packages/airflow/models/taskinstance.py", line 1514, in _execute_task
    result = execute_callable(context=context)
  File "/home/airflow/.local/lib/python3.7/site-packages/airflow/operators/python.py", line 180, in execute
    branch = super().execute(context)
  File "/home/airflow/.local/lib/python3.7/site-packages/airflow/operators/python.py", line 151, in execute
    return_value = self.execute_callable()
  File "/home/airflow/.local/lib/python3.7/site-packages/airflow/operators/python.py", line 162, in execute_callable
    return self.python_callable(*self.op_args, **self.op_kwargs)
  File "/opt/airflow/dags/DAG-2.py", line 10, in _choose_model_to_run
    acuuracies = ti.xcom_pull(task_id=['model_A', 'model_B', 'model_C'])
  File "/home/airflow/.local/lib/python3.7/site-packages/airflow/utils/session.py", line 70, in wrapper
    return func(*args, session=session, **kwargs)
TypeError: xcom_pull() got an unexpected keyword argument 'task_id'
[2021-11-11 13:01:23,163] {taskinstance.py:1280} INFO - Marking task as FAILED. dag_id=dag-2, task_id=model_D, execution_date=20211111T130119, start_date=20211111T130122, end_date=20211111T130123
[2021-11-11 13:01:23,181] {standard_task_runner.py:91} ERROR - Failed to execute job 18 for task model_D
Traceback (most recent call last):
  File "/home/airflow/.local/lib/python3.7/site-packages/airflow/task/task_runner/standard_task_runner.py", line 85, in _start_by_fork
    args.func(args, dag=self.dag)
  File "/home/airflow/.local/lib/python3.7/site-packages/airflow/cli/cli_parser.py", line 48, in command
    return func(*args, **kwargs)
  File "/home/airflow/.local/lib/python3.7/site-packages/airflow/utils/cli.py", line 92, in wrapper
    return f(*args, **kwargs)
  File "/home/airflow/.local/lib/python3.7/site-packages/airflow/cli/commands/task_command.py", line 292, in task_run
    _run_task_by_selected_method(args, dag, ti)
  File "/home/airflow/.local/lib/python3.7/site-packages/airflow/cli/commands/task_command.py", line 107, in _run_task_by_selected_method
    _run_raw_task(args, ti)
  File "/home/airflow/.local/lib/python3.7/site-packages/airflow/cli/commands/task_command.py", line 184, in _run_raw_task
    error_file=args.error_file,
  File "/home/airflow/.local/lib/python3.7/site-packages/airflow/utils/session.py", line 70, in wrapper
    return func(*args, session=session, **kwargs)
  File "/home/airflow/.local/lib/python3.7/site-packages/airflow/models/taskinstance.py", line 1332, in _run_raw_task
    self._execute_task_with_callbacks(context)
  File "/home/airflow/.local/lib/python3.7/site-packages/airflow/models/taskinstance.py", line 1458, in _execute_task_with_callbacks
    result = self._execute_task(context, self.task)
  File "/home/airflow/.local/lib/python3.7/site-packages/airflow/models/taskinstance.py", line 1514, in _execute_task
    result = execute_callable(context=context)
  File "/home/airflow/.local/lib/python3.7/site-packages/airflow/operators/python.py", line 180, in execute
    branch = super().execute(context)
  File "/home/airflow/.local/lib/python3.7/site-packages/airflow/operators/python.py", line 151, in execute
    return_value = self.execute_callable()
  File "/home/airflow/.local/lib/python3.7/site-packages/airflow/operators/python.py", line 162, in execute_callable
    return self.python_callable(*self.op_args, **self.op_kwargs)
  File "/opt/airflow/dags/DAG-2.py", line 10, in _choose_model_to_run
    acuuracies = ti.xcom_pull(task_id=['model_A', 'model_B', 'model_C'])
  File "/home/airflow/.local/lib/python3.7/site-packages/airflow/utils/session.py", line 70, in wrapper
    return func(*args, session=session, **kwargs)
TypeError: xcom_pull() got an unexpected keyword argument 'task_id'
[2021-11-11 13:01:23,196] {local_task_job.py:154} INFO - Task exited with return code 1
[2021-11-11 13:01:23,247] {local_task_job.py:264} INFO - 0 downstream tasks scheduled from follow-on schedule check
